Workbook

Sheet Sheet
A1: TEST | B1: 改款/推薦 | C1: 系列 | D1: 圖片 | E1: 型號 | F1: 品名 | G1: 色號名稱 | H1: 樣品色號 | I1: 尺寸 | J1: 訂價 | K1: 特色
C2: ALLWEATHER | D2: =U2 | E2: 1128850 | F2: DRY-TEC FULL-ZIP RAIN PANTS MEN'S | G2: BK | H2: BK | I2: =VLOOKUP(H2,[1]尺寸簡表!$C$3:$D$1263,2,0) | J2: 4040 | K2: ◎ 重量：280g、 材質：50D抗撕裂尼龍表布，DRYTEC® 3L(耐水壓20,000mm+，透氣度17,000g/㎡)，布料不含 PFAS。
C3: ALLWEATHER | D3: =U3 | E3: 1128851 | F3: DRY-TEC FULL-ZIP RAIN PANTS WOMEN'S | G3: BK | H3: BK | I3: =VLOOKUP(H3,[1]尺寸簡表!$C$3:$D$1263,2,0) | J3: 3880 | K3: ◎ 重量：264g、 材質：50D抗撕裂尼龍表布，DRYTEC® 3L(耐水壓20,000mm+，透氣度17,000g/㎡)，布料不含 PFAS。
A4: 促銷款 | B4: 活動款 | C4: ALLWEATHER | D4: =U4 | E4: 1128848 | F4: DRY-TEC RAIN PANTS MEN'S | G4: BK | H4: BK | I4: =VLOOKUP(H4,[1]尺寸簡表!$C$3:$D$1263,2,0) | J4: 2900 | K4: ◎ 重量：233g、 材質：50D抗撕裂尼龍表布，DRYTEC® 3L(耐水壓20,000mm+，透氣度17,000g/㎡)，布料不含 PFAS。
A5: 促銷款 | B5: 活動款 | C5: ALLWEATHER | D5: =U5 | E5: 1128849 | F5: DRY-TEC RAIN PANTS WOMEN'S | G5: GY NV | H5: NV | I5: =VLOOKUP(H5,[1]尺寸簡表!$C$3:$D$1263,2,0) | J5: 2900 | K5: ◎ 重量：217g、 材質：50D抗撕裂尼龍表布，DRYTEC® 3L(耐水壓20,000mm+，透氣度17,000g/㎡)，布料不含 PFAS。
C6: ALLWEATHER | D6: =U6 | E6: 1128842 | F6: GORE-TEX FULL-ZIP RAIN PANTS MEN'S | G6: BK NV | H6: NV | I6: =VLOOKUP(H6,[1]尺寸簡表!$C$3:$D$1263,2,0) | J6: 7770 | K6: ◎ 20D 尼龍抗撕裂表布，GORE-TEX® C-Knit 3L(耐水壓20,000mm，透氣度24,000g/㎡)，平均重量 : 205 g。 ◎ GORE-TEX 全開式拉鍊雨褲，不含PFAS。
C7: ALLWEATHER | D7: =U7 | E7: 1128843 | F7: GORE-TEX FULL-ZIP RAIN PANTS WOMEN'S | G7: DGY | H7: DGY | I7: =VLOOKUP(H7,[1]尺寸簡表!$C$3:$D$1263,2,0) | J7: 7380 | K7: ◎ 20D 尼龍抗撕裂表布，GORE-TEX® C-Knit 3L(耐水壓20,000mm，透氣度24,000g/㎡)，平均重量 : 193 g。 ◎ GORE-TEX 全開式拉鍊雨褲，不含PFAS。
C8: ALLWEATHER | D8: =U8 | E8: 1128840 | F8: GORE-TEX RAIN PANTS MEN'S | G8: BK GY | H8: GY | I8: =VLOOKUP(H8,[1]尺寸簡表!$C$3:$D$1263,2,0) | J8: 6540 | K8: ◎ 20D 尼龍抗撕裂表布，GORE-TEX® C-Knit 3L(耐水壓20,000mm，透氣度24,000g/㎡)，平均重量 : 181 g。 ◎ GORE-TEX 輕量雨褲，不含PFAS。
C9: ALLWEATHER | D9: =U9 | E9: 1128841 | F9: GORE-TEX RAIN PANTS WOMEN'S | G9: GY NV | H9: NV | I9: =VLOOKUP(H9,[1]尺寸簡表!$C$3:$D$1263,2,0) | J9: 6150 | K9: ◎ 20D 尼龍抗撕裂表布，GORE-TEX® C-Knit 3L(耐水壓20,000mm，透氣度24,000g/㎡)，平均重量 : 167 g。 ◎ GORE-TEX 輕量雨褲，不含PFAS。
C10: ALLWEATHER | D10: =U10 | E10: 1128687 | F10: LIGHT WEIGHT RAIN WRAP | G10: BL DGN IV | H10: IV | I10: =VLOOKUP(H10,[1]尺寸簡表!$C$3:$D$1263,2,0) | J10: 1330 | K10: ◎ 重量：71g、裙長45cm（M號）、收納尺寸6x4x10cm。 ◎ 40D尼龍表布，HYDROPRO® 2L（耐水壓5,000mm）。
C11: ALLWEATHER | D11: =U11 | E11: 1128829 | F11: PACK WRAP RAIN COAT | G11: BK CN IV YGN | H11: YGN | I11: =VLOOKUP(H11,[1]尺寸簡表!$C$3:$D$1263,2,0) | J11: 4130 | K11: ◎ 70D 尼龍表布(超耐久撥水加工)，DRYTEC® 2L(耐水壓20,000mm+，透氣度13,000g/㎡)。 ◎ 重量 : 370g，不含 PFAS。
C12: ALLWEATHER | D12: =U12 | E12: 1128787 | F12: PACK WRAP RAIN JACKET | G12: BGN BK KH OG | H12: BGN | I12: =VLOOKUP(H12,[1]尺寸簡表!$C$3:$D$1263,2,0) | J12: 4480 | K12: ◎ 重量：295g。此款雨披外套可完全覆蓋30公升以內背包，快速應付突如其來的大雨。 ◎ 表布：70D尼龍布（撥水加工），DRYTEC®2L（耐水壓20,000mm+，透氣度13,000g/㎡），布料不含 PFAS。 ◎ 後背的背包延伸空間不用時可收納，附鬆緊帶可固定背包。
C13: ALLWEATHER | D13: =U13 | E13: 1128731 | F13: PEAK SHELL JACKET MEN'S | G13: BL NV YL | H13: BL | I13: =VLOOKUP(H13,[1]尺寸簡表!$C$3:$D$1263,2,0) | J13: 8600 | K13: ◎ 重量：185g。 ◎ 15D Ballistic Airlight®表布（撥水加工），GORE-TEX®3L（耐水壓20,000mm+，透氣度20,000g/㎡）、「K-MONO CUT™」一體式剪裁。
C14: ALLWEATHER | D14: =U14 | E14: 1128732 | F14: PEAK SHELL JACKET WOMEN'S | G14: DGY PU TQ | H14: PU | I14: =VLOOKUP(H14,[1]尺寸簡表!$C$3:$D$1263,2,0) | J14: 8600 | K14: ◎ 重量：166g。 ◎ 15D Ballistic Airlight®表布（撥水加工），GORE-TEX®3L（耐水壓20,000mm+，透氣度20,000g/㎡）、「K-MONO CUT™」一體式剪裁。
C15: ALLWEATHER | D15: =U15 | E15: 1128668 | F15: PRINT TREKKING RAIN PONCHO | G15: IV PIGN | I15: =VLOOKUP(H15,[1]尺寸簡表!$C$3:$D$1263,2,0) | J15: 3040 | K15: ◎ 輕便雨披，可背負背包用。重量：295g、收納尺寸：9×9×14cm。 ◎ 40D 尼龍表布，HYDROPRO® 2L 防水塗層(耐水壓5,000mm)。
A16: 促銷款 | B16: 活動款 | C16: ALLWEATHER | D16: =U16 | E16: 1128821 | F16: RAIN DANCER JACKET MEN'S | G16: BGY BL DGN LGY OG YL | H16: BGY | I16: =VLOOKUP(H16,[1]尺寸簡表!$C$3:$D$1263,2,0) | J16: 5020 | K16: ◎ 40D 尼龍抗撕裂表布，(SUPER) DRYTEC 3L（耐水壓20,000mm+，透氣度32,000g/㎡），布料不含 PFAS，平均重量 : 317 g。 ◎ 「K-MONOCUT™」一體式剪裁。
A17: 促銷款 | B17: 活動款 | C17: ALLWEATHER | D17: =U17 | E17: 1128822 | F17: RAIN DANCER JACKET WOMEN'S | G17: BK LGY RAS YL | H17: YL | I17: =VLOOKUP(H17,[1]尺寸簡表!$C$3:$D$1263,2,0) | J17: 4680 | K17: ◎ 40D 尼龍抗撕裂表布，(SUPER) DRYTEC 3L（耐水壓20,000mm+，透氣度32,000g/㎡），布料不含 PFAS。 ◎ 「K-MONOCUT™」一體式剪裁。
C18: ALLWEATHER | D18: =U18 | E18: 1128776 | F18: RAIN HIKER JACKET MEN'S | G18: BL KH NV OG | H18: OG KH | I18: =VLOOKUP(H18,[1]尺寸簡表!$C$3:$D$1263,2,0) | J18: 3580 | K18: ◎ 重量：265g、「K-MONO CUT™」一體式剪裁大量減少布料接縫，實現防水、輕量、耐磨的高性能。 ◎ 表布：70D抗撕裂尼龍布(撥水加工)，DRYTEC® 2L(耐水壓20,000mm+，透氣度13,000g/㎡)，布料不含 PFAS。
C19: ALLWEATHER | D19: =U19 | E19: 1128777 | F19: RAIN HIKER JACKET WOMEN'S | G19: KH LBL PU TQ | H19: LBL PU | I19: =VLOOKUP(H19,[1]尺寸簡表!$C$3:$D$1263,2,0) | J19: 3270 | K19: ◎ 重量：239g、「K-MONO CUT™」一體式剪裁大量減少布料接縫，實現防水、輕量、耐磨的高性能。 ◎ 表布：70D抗撕裂尼龍布(撥水加工)，DRYTEC® 2L(耐水壓20,000mm+，透氣度13,000g/㎡)，布料不含 PFAS。
C20: ALLWEATHER | D20: =U20 | E20: 1128825 | F20: RAIN HIKER PANTS MEN'S | G20: BK OG | H20: OG | I20: =VLOOKUP(H20,[1]尺寸簡表!$C$3:$D$1263,2,0) | J20: 2100 | K20: ◎ 70D 尼龍表布(超耐久撥水加工)，DRYTEC® 2L(耐水壓20,000mm+，透氣度13,000g/㎡)。 ◎ 重量 : 183g，不含 PFAS。
C21: ALLWEATHER | D21: =U21 | E21: 1128826 | F21: RAIN HIKER PANTS WOMEN'S | G21: BK | H21: BK | I21: =VLOOKUP(H21,[1]尺寸簡表!$C$3:$D$1263,2,0) | J21: 2100 | K21: ◎ 70D 尼龍表布(超耐久撥水加工)，DRYTEC® 2L(耐水壓20,000mm+，透氣度13,000g/㎡)。 ◎ 重量 : 172g，不含 PFAS。
C22: ALLWEATHER | D22: =U22 | E22: 1128729 | F22: RAIN TREKKER JACKET MEN'S | G22: BK DGN NV RD YL | H22: YL NV BK | I22: =VLOOKUP(H22,[1]尺寸簡表!$C$3:$D$1263,2,0) | J22: 7680 | K22: ◎ 重量：301g。 ◎ 50D Ballistic®表布，GORE-TEX®3L（耐水壓20,000mm+，透氣度20,000g/㎡）、「K-MONOCUT™」一體式剪裁。
C23: ALLWEATHER | D23: =U23 | E23: 1128730 | F23: RAIN TREKKER JACKET WOMEN'S | G23: IV KH PK PU TQ | H23: PU TQ PK KH | I23: =VLOOKUP(H23,[1]尺寸簡表!$C$3:$D$1263,2,0) | J23: 7680 | K23: ◎ 重量：272g。 ◎ 50D Ballistic®表布，GORE-TEX®3L（耐水壓20,000mm+，透氣度20,000g/㎡）、「K-MONOCUT™」一體式剪裁。
C24: ALLWEATHER | D24: =U24 | E24: 1128640 | F24: RAIN WRAP SKIRT | G24: GY TN | H24: TN | I24: =VLOOKUP(H24,[1]尺寸簡表!$C$3:$D$1263,2,0) | J24: 1600 | K24: ◎ 50D 尼龍表布，DRYTEC® 3L(耐水壓20,000mm，透氣度15,000g/㎡)。 ◎ 裙長：62cm（M尺寸）、收納尺寸：6×6×14cm。
C25: ALLWEATHER | D25: =U25 | E25: 1128747 | F25: RAMBLER RAIN COAT MEN'S | G25: BK TN | I25: =VLOOKUP(H25,[1]尺寸簡表!$C$3:$D$1263,2,0) | J25: 7060 | K25: ◎ 重量：429g。 ◎ 50D DRYTEC®3L（耐水壓20,000mm+，透氣度15,000g/㎡）。
C26: ALLWEATHER | D26: =U26 | E26: 1128748 | F26: RAMBLER RAIN COAT WOMEN'S | G26: IV KH NV | H26: IV | I26: =VLOOKUP(H26,[1]尺寸簡表!$C$3:$D$1263,2,0) | J26: 6660 | K26: ◎ 重量：366g。 ◎ 50D DRYTEC®3L（耐水壓20,000mm+，透氣度15,000g/㎡）。
C27: ALLWEATHER | D27: =U27 | E27: 1128733 | F27: STORM CRUISER JACKET MEN'S | G27: BGN BK BL26 RD YL | H27: BGN BL26 YL | I27: =VLOOKUP(H27,[1]尺寸簡表!$C$3:$D$1263,2,0) | J27: 7100 | K27: ◎ 重量：254g。 ◎ 30D Ballistic® 尼龍，(SUPER) DRYTEC 3L（耐水壓20,000mm+，透氣度40,000g/㎡）、「K-MONO CUT™」一體式剪裁。
C28: ALLWEATHER | D28: =U28 | E28: 1128735 | F28: STORM CRUISER JACKET WOMEN'S | G28: DGY IV PK TQ YL | H28: TQ | I28: =VLOOKUP(H28,[1]尺寸簡表!$C$3:$D$1263,2,0) | J28: 7100 | K28: ◎ 重量：225g。 ◎ 30D Ballistic®尼龍，(SUPER) DRYTEC 3L（耐水壓20,000mm+，透氣度40,000g/㎡）、「K-MONO CUT™」一體式剪裁。
C29: ALLWEATHER | D29: =U29 | E29: 1128846 | F29: SUPER DRY-TEC FULL-ZIP RAIN PANTS MEN'S | G29: BK NV | H29: NV | I29: =VLOOKUP(H29,[1]尺寸簡表!$C$3:$D$1263,2,0) | J29: 5440 | K29: ◎ 30D 尼龍抗撕裂表布，(SUPER) DRYTEC® 3L(耐水壓20,000mm+，透氣度52,700g/㎡)，平均重量 : 219 g。 ◎ 防水超透氣全開拉鍊雨褲，不含PFAS。
C30: ALLWEATHER | D30: =U30 | E30: 1128847 | F30: SUPER DRY-TEC FULL-ZIP RAIN PANTS WOMEN'S | G30: BK | H30: BK | I30: =VLOOKUP(H30,[1]尺寸簡表!$C$3:$D$1263,2,0) | J30: 5160 | K30: ◎ 30D 尼龍抗撕裂表布，(SUPER) DRYTEC® 3L(耐水壓20,000mm+，透氣度52,700g/㎡)，平均重量 : 204 g。 ◎ 防水超透氣全開拉鍊雨褲，不含PFAS。
C31: ALLWEATHER | D31: =U31 | E31: 1128844 | F31: SUPER DRY-TEC RAIN PANTS MEN'S | G31: BK GY NV RD | H31: RD | I31: =VLOOKUP(H31,[1]尺寸簡表!$C$3:$D$1263,2,0) | J31: 4320 | K31: ◎ 30D 尼龍抗撕裂表布，(SUPER) DRYTEC® 3L(耐水壓20,000mm+，透氣度52,700g/㎡)，平均重量 : 197 g。 ◎ 輕量防水超透氣全開拉鍊雨褲，不含PFAS。
C32: ALLWEATHER | D32: =U32 | E32: 1128845 | F32: SUPER DRY-TEC RAIN PANTS WOMEN'S | G32: BK NV TQ | H32: TQ | I32: =VLOOKUP(H32,[1]尺寸簡表!$C$3:$D$1263,2,0) | J32: 3990 | K32: ◎ 30D 尼龍抗撕裂表布，(SUPER) DRYTEC® 3L(耐水壓20,000mm+，透氣度52,700g/㎡)，平均重量 : 181 g。 ◎ 輕量防水超透氣全開拉鍊雨褲，不含PFAS。
C33: ALLWEATHER | D33: =U33 | E33: 1128784 | F33: SUPER DRY-TEC STRETCH RAIN PANTS MEN'S | G33: BK BL | H33: BK | I33: =VLOOKUP(H33,[1]尺寸簡表!$C$3:$D$1263,2,0) | J33: 4940 | K33: ◎ 重量：172g。15D Ballistic Airlight®表布，(SUPER) DRYTEC 3L（耐水壓20,000mm+，透氣度50,000g/㎡），不含PFAS。
C34: ALLWEATHER | D34: =U34 | E34: 1128785 | F34: SUPER DRY-TEC STRETCH RAIN PANTS WOMEN'S | G34: BK GY | H34: BK | I34: =VLOOKUP(H34,[1]尺寸簡表!$C$3:$D$1263,2,0) | J34: 4630 | K34: ◎ 重量：158g。15D Ballistic Airlight®表布，(SUPER) DRYTEC 3L（耐水壓20,000mm+，透氣度50,000g/㎡），不含PFAS。
C35: ALLWEATHER | D35: =U35 | E35: 1128745 | F35: SUPER DRY-TEC U.L. RAIN PANTS MEN'S | G35: BK | H35: BK | I35: =VLOOKUP(H35,[1]尺寸簡表!$C$3:$D$1263,2,0) | J35: 4800 | K35: ◎ 重量：116g。 ◎ 7D Ballistic Airlight®表布，(SUPER) DRYTEC 3L（耐水壓20,000mm+，透氣度50,000g/㎡）。
C36: ALLWEATHER | D36: =U36 | E36: 1128746 | F36: SUPER DRY-TEC U.L. RAIN PANTS WOMEN'S | G36: DGY | I36: =VLOOKUP(H36,[1]尺寸簡表!$C$3:$D$1263,2,0) | J36: 4800 | K36: ◎ 7D Ballistic Airlight®表布，(SUPER) DRYTEC 3L（耐水壓20,000mm+，透氣度50,000g/㎡）。
C37: ALLWEATHER | D37: =U37 | E37: 1128721 | F37: TEMPEST JACKET MEN'S | G37: BL KH NV OG RD | H37: OG BL NV KH | I37: =VLOOKUP(H37,[1]尺寸簡表!$C$3:$D$1263,2,0) | J37: 9200 | K37: ◎ 重量：247g。 ◎ 20D GORE-TEX® 3L（耐水壓20,000mm+，透氣度20,000g/㎡）、「K-MONO CUT™」一體式剪裁。
C38: ALLWEATHER | D38: =U38 | E38: 1128723 | F38: TEMPEST JACKET WOMEN'S | G38: LBL LGN NV PK TQ | H38: LBL NV TQ | I38: =VLOOKUP(H38,[1]尺寸簡表!$C$3:$D$1263,2,0) | J38: 9200 | K38: ◎ 重量：223g。 ◎ 20D GORE-TEX® 3L（耐水壓20,000mm+，透氣度20,000g/㎡）、「K-MONO CUT™」一體式剪裁。
C39: ALLWEATHER | D39: =U39 | E39: 1128770 | F39: THUNDER PASS JACKET MEN'S | G39: BK BL DGY GN RD TN YL | H39: RD BL GN TN DGY YL | I39: =VLOOKUP(H39,[1]尺寸簡表!$C$3:$D$1263,2,0) | J39: 4400 | K39: ◎ 重量：324g、 材質：50D抗撕裂尼龍表布(撥水加工)，DRYTEC® 3L(耐水壓20,000mm+，透氣度17,000g/㎡)，布料不含 PFAS。 ◎ 前襟拉鍊為防水拉鍊（口袋拉鍊有蓋片），重量輕。
C40: ALLWEATHER | D40: =U40 | E40: 1128771 | F40: THUNDER PASS JACKET WOMEN'S | G40: BN IV LBL RD TQ | H40: IV TQ RD BN LBL | I40: =VLOOKUP(H40,[1]尺寸簡表!$C$3:$D$1263,2,0) | J40: 4400 | K40: ◎ 重量：298g、 材質：50D抗撕裂尼龍表布(撥水加工)，DRYTEC® 3L(耐水壓20,000mm+，透氣度17,000g/㎡)，布料不含 PFAS。 ◎ 前襟拉鍊為防水拉鍊（口袋拉鍊有蓋片），重量輕。
...
